Workbook

Sheet ฐานคำนวณ
A1: ฐานในการคำนวณและช่วงเงินเดือนสำหรับการเลื่อนเงินเดือน
B2: 1 | C2: 2 | D2: 3 | E2: 4 | F2: 5
B3: ระดับตำแหน่ง | C3: เงินเดือนเต็มขั้น (ทะลุบัญชี) | F3: ค่ากลาง
D4: ฐานบน | E4: ฐานล่าง
A5: 1 | B5: ชำนาญการ | C5: 58390 | D5: 36470 | E5: 24410 | F5: 29330
A6: 2 | B6: ชำนาญการพิเศษ | C6: 69040 | D6: 49330 | E6: 37200 | F6: 40270
A7: 3 | B7: ชำนาญงาน | C7: 54820 | D7: 31610 | E7: 18480 | F7: 24470
A8: 4 | B8: เชี่ยวชาญ | C8: 74320 | D8: 59630 | E8: 50320 | F8: 50320
A9: 5 | B9: ทรงคุณวุฒิ | C9: 76800 | D9: 66700 | E9: 60830 | F9: 60830 | H9: นิติกรทรงคุณวุฒิ เมื่อได้รับเงินเดือนถึง (74,320) แล้ว ให้ใช้ฐาน ทรงคุณวุฒิระดับบน 2
A10: 6 | B10: ทรงคุณวุฒิ2 | C10: 76800 | D10: 68560 | E10: 60830 | F10: 60830
A11: 7 | B11: ทักษะพิเศษ | C11: 74320 | D11: 63840 | E11: 53430 | F11: 58630
A12: 8 | B12: บริหารต้น | C12: 76800 | D12: 68530 | E12: 62210 | F12: 62730
A13: 9 | B13: บริหารสูง | C13: 76800 | D13: 71700 | E13: 69910 | F13: 69910
A14: 10 | B14: ปฏิบัติการ | C14: 43600 | D14: 23930 | E14: 17980 | F14: 20950
A15: 11 | B15: ปฏิบัติงาน | C15: 38750 | D15: 18110 | E15: 12310 | F15: 15210
A16: 12 | B16: อาวุโส | C16: 69040 | D16: 35070 | E16: 32250 | F16: 32250 | H16: อาวุโส2 ใช้สำหรับ ขรก ระดับอาวุโส ที่เงินยังไม่ถึงขั้นสูงของระดับบน 1 (41,620) ใช้ฐาน 35,070
A17: 13 | B17: อาวุโส2 | C17: 69040 | D17: 44970 | E17: 32250 | F17: 35120 | H17: แต่ถ้าเป็นอาวุโส แล้วเงินเกินขั้นสูงของฐานบน 1 (41,620) แล้ว ให้ไปใช้ฐานบน 2 (44,970)
A18: 14 | B18: อำนวยการต้น | C18: 70360 | D18: 51290 | E18: 37210 | F18: 43080
A19: 15 | B19: อำนวยการสูง | C19: 74320 | D19: 60990 | E19: 52320 | F19: 52320
A22: เลือกประเภทตำแหน่ง | C22: ทั่วไป | D22: วิชาการ | E22: อำนวยการ | F22: บริหาร
A23: เจ้าพนักงานธุรการ | C23: ปฏิบัติงาน | D23: ปฏิบัติการ | E23: อำนวยการต้น | F23: บริหารต้น
A24: เจ้าพนักงานการเงินและบัญชี | C24: ชำนาญงาน | D24: ชำนาญการ | E24: อำนวยการสูง | F24: บริหารสูง
A25: เจ้าพนักงานพัสดุ | C25: อาวุโส | D25: ชำนาญการพิเศษ
A26: เจ้าพนักงานโสตทัศนศึกษา | C26: อาวุโส* | D26: เชี่ยวชาญ
A27: เจ้าพนักงานห้องสมุด | C27: ทักษะพิเศษ | D27: ทรงคุณวุฒิ
A28: นายช่างโยธา | D28: ทรงคุณวุฒิ*
A29: นักการข่าว
A30: นักจัดการงานทั่วไป
A31: นักทรัพยากรบุคคล
A32: นักประชาสัมพันธ์
A33: นักวิเคราะห์นโยบายและแผน
A34: นักวิชาการคอมพิวเตอร์
A35: นักวิชาการเงินและบัญชี
A36: นักวิชาการตรวจสอบภายใน
A37: นักวิชาการพัสดุ
A38: นักวิชาการยุติธรรม
A39: นักวิชาการโสตทัศนศึกษา
A40: นักวิเทศสัมพันธ์
... A45: สถาปนิก

Sheet retire-non-gfp
C1: แบบฟอร์มประมาณการ บำเหน็จ บำนาญ ของข้าราชการในสังกัดสำนักงานปลัดกระทรวงยุติธรรม | L1: ห้ามลบ แถวนี้
L2: ห้ามลบ แถวนี้
L3: ห้ามลบ แถวนี้
A4: นาย/นางสาว | E4: ผู้อำนวยการกอง | I4: ระดับ | J4: อำนวยการต้น | L4: ห้ามลบ แถวนี้
A5: วัน/เดือน/ปี เกิด | C5: 23839 | F5: อายุ | G5: =YEARFRAC(C5,H6) -> 60.483333 | L5: ห้ามลบ แถวนี้
A6: วันเริ่มรับราชการ | C6: 35464 | F6: วันที่ เกษียณอายุ/ลาออก | H6: 45931 | L6: ห้ามลบ แถวนี้
L7: ห้ามลบ แถวนี้
A8: คำนวณเวลาราชการ | E8: ปี | F8: เดือน | G8: วัน | I8: % ที่เลื่อนย้อนหลัง | K8: รวม | L8: ห้ามลบ แถวนี้
A9: เวลาราชการ | E9: =DATEDIF(C6,H6,"Y") -> 28 | F9: =DATEDIF(C6,H6,"YM") -> 7 | G9: =DATEDIF(C6,H6,"MD") -> 28 | I9: 1/2567 | J9: 3 | K9: =SUM(J9:J14) -> 19.4 | L9: ห้ามลบ แถวนี้
A10: เวลาราชการทวีคูณ | I10: 2/2566 | J10: 3.3 | L10: ห้ามลบ แถวนี้
A11: - ปี 19 (7 ต.ค. 19 - 5 ม.ค. 20) | I11: 1/2566 | J11: 3.3 | K11: เฉลี่ย | L11: ห้ามลบ แถวนี้
A12: - ปี 34 (23 ก.พ. 34 - 2 พ.ค. 34) | I12: 2/2565 | J12: 3.2 | K12: =ROUND(K9/6,1) -> 3.2 | L12: ห้ามลบ แถวนี้
A13: เวลาราชการ | E13: =E9+E11+E12 -> 28 | F13: =F9+F11+F12 -> 7 | G13: =G9+G11+G12 -> 28 | I13: 1/2565 | J13: 3.3 | L13: ห้ามลบ แถวนี้
A14: รวมเวลาราชการ | E14: =E13+(F13/12)+(G13/365) -> 28.660046 | I14: 2/2564 | J14: 3.3 | L14: ห้ามลบ แถวนี้
L15: ห้ามลบ แถวนี้
A16: รอบการประเมิน | B16: ระดับตำแหน่ง | C16: เงินเดือนเดิม | D16: เงินเดือนขั้นสูง | E16: ฐาน | F16: % ที่เลื่อน (เฉลี่ย) | G16: เงินที่เลื่อน | H16: เงินที่เลื่อนจริง | I16: เงินเดือนใหม่ | J16: จำนวนเดือน | K16: เงินเดือนใหม่ x จำนวนเดือน | L16: ห้ามลบ แถวนี้
L17: ห้ามลบ แถวนี้
A18: 44287 | B18: ชำนาญการพิเศษ | C18: 39310 | D18: =INDEX(ฐานคำนวณ!$C$5:$C$19,MATCH(B18,ฐานคำนวณ!$B$5:$B$19,0)) -> 69040 | E18: =_xlfn.IFS(C18="","",C18>INDEX(ฐานคำนวณ!$F$5:$F$19,MATCH(B18,ฐานคำนวณ!$B$5:$B$19,0)),INDEX(ฐานคำนวณ!$D$5:$D$19,MATCH(B18,ฐานคำนวณ!$B$5:$B$19,0)),TRUE,INDEX(ฐานคำนวณ!$E$5:$E$19,MATCH(B18,ฐานคำนวณ!$B$5:$B$19,0))) -> 37200 | F18: 3.9 | G18: =ROUND(E18*F18%,2) -> 1450.8 | H18: =IF(C18+ROUNDUP(G18,-1)>=D18,D18-C18,ROUNDUP(G18,-1)) -> 1460 | I18: =C18+H18 -> 40770 | L18: ห้ามลบ แถวนี้
A19: 44470 | B19: ชำนาญการพิเศษ | C19: =I18 -> 40770 | D19: =INDEX(ฐานคำนวณ!$C$5:$C$19,MATCH(B19,ฐานคำนวณ!$B$5:$B$19,0)) -> 69040 | E19: =_xlfn.IFS(C19="","",C19>INDEX(ฐานคำนวณ!$F$5:$F$19,MATCH(B19,ฐานคำนวณ!$B$5:$B$19,0)),INDEX(ฐานคำนวณ!$D$5:$D$19,MATCH(B19,ฐานคำนวณ!$B$5:$B$19,0)),TRUE,INDEX(ฐานคำนวณ!$E$5:$E$19,MATCH(B19,ฐานคำนวณ!$B$5:$B$19,0))) -> 49330 | F19: 4.2 | G19: =ROUND(E19*F19%,2) -> 2071.86 | H19: =IF(C19+ROUNDUP(G19,-1)>=D19,D19-C19,ROUNDUP(G19,-1)) -> 2080 | I19: =C19+H19 -> 42850
A20: 44652 | B20: ชำนาญการพิเศษ | C20: =I19 -> 42850 | D20: =INDEX(ฐานคำนวณ!$C$5:$C$19,MATCH(B20,ฐานคำนวณ!$B$5:$B$19,0)) -> 69040 | E20: =_xlfn.IFS(C20="","",C20>INDEX(ฐานคำนวณ!$F$5:$F$19,MATCH(B20,ฐานคำนวณ!$B$5:$B$19,0)),INDEX(ฐานคำนวณ!$D$5:$D$19,MATCH(B20,ฐานคำนวณ!$B$5:$B$19,0)),TRUE,INDEX(ฐานคำนวณ!$E$5:$E$19,MATCH(B20,ฐานคำนวณ!$B$5:$B$19,0))) -> 49330 | F20: 3.3 | G20: =ROUND(E20*F20%,2) -> 1627.89 | H20: =IF(C20+ROUNDUP(G20,-1)>=D20,D20-C20,ROUNDUP(G20,-1)) -> 1630 | I20: =C20+H20 -> 44480
A21: 44835 | B21: ชำนาญการพิเศษ | C21: =I20 -> 44480 | D21: =INDEX(ฐานคำนวณ!$C$5:$C$19,MATCH(B21,ฐานคำนวณ!$B$5:$B$19,0)) -> 69040 | E21: =_xlfn.IFS(C21="","",C21>INDEX(ฐานคำนวณ!$F$5:$F$19,MATCH(B21,ฐานคำนวณ!$B$5:$B$19,0)),INDEX(ฐานคำนวณ!$D$5:$D$19,MATCH(B21,ฐานคำนวณ!$B$5:$B$19,0)),TRUE,INDEX(ฐานคำนวณ!$E$5:$E$19,MATCH(B21,ฐานคำนวณ!$B$5:$B$19,0))) -> 49330 | F21: 3.2 | G21: =ROUND(E21*F21%,2) -> 1578.56 | H21: =IF(C21+ROUNDUP(G21,-1)>=D21,D21-C21,ROUNDUP(G21,-1)) -> 1580 | I21: =C21+H21 -> 46060
A22: 45017 | B22: ชำนาญการพิเศษ | C22: =I21 -> 46060 | D22: =INDEX(ฐานคำนวณ!$C$5:$C$19,MATCH(B22,ฐานคำนวณ!$B$5:$B$19,0)) -> 69040 | E22: =_xlfn.IFS(C22="","",C22>INDEX(ฐานคำนวณ!$F$5:$F$19,MATCH(B22,ฐานคำนวณ!$B$5:$B$19,0)),INDEX(ฐานคำนวณ!$D$5:$D$19,MATCH(B22,ฐานคำนวณ!$B$5:$B$19,0)),TRUE,INDEX(ฐานคำนวณ!$E$5:$E$19,MATCH(B22,ฐานคำนวณ!$B$5:$B$19,0))) -> 49330 | F22: 3.3 | G22: =ROUND(E22*F22%,2) -> 1627.89 | H22: =IF(C22+ROUNDUP(G22,-1)>=D22,D22-C22,ROUNDUP(G22,-1)) -> 1630 | I22: =C22+H22 -> 47690
A23: 45200 | B23: ชำนาญการพิเศษ | C23: =I22 -> 47690 | D23: =INDEX(ฐานคำนวณ!$C$5:$C$19,MATCH(B23,ฐานคำนวณ!$B$5:$B$19,0)) -> 69040 | E23: =_xlfn.IFS(C23="","",C23>INDEX(ฐานคำนวณ!$F$5:$F$19,MATCH(B23,ฐานคำนวณ!$B$5:$B$19,0)),INDEX(ฐานคำนวณ!$D$5:$D$19,MATCH(B23,ฐานคำนวณ!$B$5:$B$19,0)),TRUE,INDEX(ฐานคำนวณ!$E$5:$E$19,MATCH(B23,ฐานคำนวณ!$B$5:$B$19,0))) -> 49330 | F23: 3.3 | G23: =ROUND(E23*F23%,2) -> 1627.89 | H23: =IF(C23+ROUNDUP(G23,-1)>=D23,D23-C23,ROUNDUP(G23,-1)) -> 1630 | I23: =C23+H23 -> 49320
A24: 45383 | B24: อำนวยการต้น | C24: =I23 -> 49320 | D24: =INDEX(ฐานคำนวณ!$C$5:$C$19,MATCH(B24,ฐานคำนวณ!$B$5:$B$19,0)) -> 70360 | E24: =_xlfn.IFS(C24="","",C24>INDEX(ฐานคำนวณ!$F$5:$F$19,MATCH(B24,ฐานคำนวณ!$B$5:$B$19,0)),INDEX(ฐานคำนวณ!$D$5:$D$19,MATCH(B24,ฐานคำนวณ!$B$5:$B$19,0)),TRUE,INDEX(ฐานคำนวณ!$E$5:$E$19,MATCH(B24,ฐานคำนวณ!$B$5:$B$19,0))) -> 51290 | F24: 4 | G24: =ROUND(E24*F24%,2) -> 2051.6 | H24: =IF(C24+ROUNDUP(G24,-1)>=D24,D24-C24,ROUNDUP(G24,-1)) -> 2060 | I24: =C24+H24 -> 51380
A25: 45566 | B25: อำนวยการต้น | C25: =I24 -> 51380 | D25: =INDEX(ฐานคำนวณ!$C$5:$C$19,MATCH(B25,ฐานคำนวณ!$B$5:$B$19,0)) -> 70360 | E25: =_xlfn.IFS(C25="","",C25>INDEX(ฐานคำนวณ!$F$5:$F$19,MATCH(B25,ฐานคำนวณ!$B$5:$B$19,0)),INDEX(ฐานคำนวณ!$D$5:$D$19,MATCH(B25,ฐานคำนวณ!$B$5:$B$19,0)),TRUE,INDEX(ฐานคำนวณ!$E$5:$E$19,MATCH(B25,ฐานคำนวณ!$B$5:$B$19,0))) -> 51290 | F25: 4.2 | G25: =ROUND(E25*F25%,2) -> 2154.18 | H25: =IF(C25+ROUNDUP(G25,-1)>=D25,D25-C25,ROUNDUP(G25,-1)) -> 2160 | I25: =C25+H25 -> 53540
A26: 45748 | B26: อำนวยการต้น | C26: =I25 -> 53540 | D26: =INDEX(ฐานคำนวณ!$C$5:$C$19,MATCH(B26,ฐานคำนวณ!$B$5:$B$19,0)) -> 70360 | E26: =_xlfn.IFS(C26="","",C26>INDEX(ฐานคำนวณ!$F$5:$F$19,MATCH(B26,ฐานคำนวณ!$B$5:$B$19,0)),INDEX(ฐานคำนวณ!$D$5:$D$19,MATCH(B26,ฐานคำนวณ!$B$5:$B$19,0)),TRUE,INDEX(ฐานคำนวณ!$E$5:$E$19,MATCH(B26,ฐานคำนวณ!$B$5:$B$19,0))) -> 51290 | F26: 3.2 | G26: =ROUND(E26*F26%,2) -> 1641.28 | H26: =IF(C26+ROUNDUP(G26,-1)>=D26,D26-C26,ROUNDUP(G26,-1)) -> 1650 | I26: =C26+H26 -> 55190
A27: 45930 | B27: อำนวยการต้น | C27: =I26 -> 55190 | D27: =INDEX(ฐานคำนวณ!$C$5:$C$19,MATCH(B27,ฐานคำนวณ!$B$5:$B$19,0)) -> 70360 | E27: =_xlfn.IFS(C27="","",C27>INDEX(ฐานคำนวณ!$F$5:$F$19,MATCH(B27,ฐานคำนวณ!$B$5:$B$19,0)),INDEX(ฐานคำนวณ!$D$5:$D$19,MATCH(B27,ฐานคำนวณ!$B$5:$B$19,0)),TRUE,INDEX(ฐานคำนวณ!$E$5:$E$19,MATCH(B27,ฐานคำนวณ!$B$5:$B$19,0))) -> 51290 | F27: 3.2 | G27: =ROUND(E27*F27%,2) -> 1641.28 | H27: =IF(C27+ROUNDUP(G27,-1)>=D27,D27-C27,ROUNDUP(G27,-1)) -> 1650 | I27: =C27+H27 -> 56840
A28: เงินเดือนเดือนสุดท้าย | I28: =I27 -> 56840 | L28: ห้ามลบ แถวนี้
L29: ห้ามลบ แถวนี้
L30: ห้ามลบ แถวนี้
L31: ห้ามลบ แถวนี้
A32: กรณีเกษียณอายุราชการปกติ (ไม่เป็นสมาชิก กบข.) | L32: ห้ามลบ แถวนี้
A33: (1) เงินบำเหน็จ (เงินเดือนเดือนสุดท้าย*อายุราชการ) หรือ | I33: =ROUND(I28*E14,2) -> 1629037 | K33: บาท | L33: ห้ามลบ แถวนี้
A34: (2) เงินบำนาญ | L34: ห้ามลบ แถวนี้
A35: บำนาญรายเดือน (เงินเดือนสุดท้าย*อายุราชการ/50) | I35: =ROUND((I28*E14)/50,2) -> 32580.74 | K35: บาท | L35: ห้ามลบ แถวนี้
A37: (3) บำเหน็จดำรงชีพ (เงินบำนาญ * 15 เท่า) | I37: =ROUND(I35*15,2) -> 488711.1 | K37: บาท | L37: ห้ามลบ แถวนี้
A38: - บำเหน็จดำรงชีพ รับครั้งที่ 1 (เมื่อเกษียณอายุ/ลาออก) | I38: =IF(I37>200000,200000,I37) -> 200000 | K38: บาท | L38: ห้ามลบ แถวนี้
A39: - บำเหน็จดำรงชีพ รับครั้งที่ 2 (อายุครบ 65 ปี) | I39: =IF(I37-I38>200000,200000,I37-I38) -> 200000 | K39: บาท | L39: ห้ามลบ แถวนี้
A40: - บำเหน็จดำรงชีพ รับครั้งที่ 3 (อายุครบ 70 ปี) | I40: =IF(I37-I38-I39>100000,100000,I37-I38-I39) -> 88711.1 | K40: บาท | L40: ห้ามลบ แถวนี้
A41: รวม รับเงินบำเหน็จดำรงชีพ | I41: =SUM(I38+I39+I40) -> 488711.1 | K41: บาท | L41: ห้ามลบ แถวนี้
...

Sheet retire-gfp
C1: แบบฟอร์มประมาณการ บำเหน็จ บำนาญ ของข้าราชการในสังกัดสำนักงานปลัดกระทรวงยุติธรรม | L1: ห้ามลบ แถวนี้
L2: ห้ามลบ แถวนี้
L3: ห้ามลบ แถวนี้
A4: นาย/นางสาว | E4: ผู้อำนวยการกอง | I4: ระดับ | J4: อำนวยการสูง | L4: ห้ามลบ แถวนี้
A5: วัน/เดือน/ปี เกิด | C5: 27760 | F5: อายุ | G5: =YEARFRAC(C5,H6) -> 60.75 | L5: ห้ามลบ แถวนี้
A6: วันเริ่มรับราชการ | C6: 37987 | F6: วันที่ เกษียณอายุ/ลาออก | H6: 49949 | L6: ห้ามลบ แถวนี้
L7: ห้ามลบ แถวนี้
A8: คำนวณเวลาราชการ | E8: ปี | F8: เดือน | G8: วัน | I8: % ที่เลื่อนย้อนหลัง | K8: รวม | L8: ห้ามลบ แถวนี้
A9: เวลาราชการ | E9: =DATEDIF(C6,H6,"Y") -> 32 | F9: =DATEDIF(C6,H6,"YM") -> 9 | G9: =DATEDIF(C6,H6,"MD") -> 0 | I9: 2/2567 | J9: 3.8 | K9: =SUM(J9:J14) -> 21.05 | L9: ห้ามลบ แถวนี้
A10: เวลาราชการทวีคูณ | I10: 1/2567 | J10: 3.3 | L10: ห้ามลบ แถวนี้
A11: - ปี 19 (7 ต.ค. 19 - 5 ม.ค. 20) | I11: 2/2566 | J11: 2.75 | K11: เฉลี่ย | L11: ห้ามลบ แถวนี้
A12: - ปี 34 (23 ก.พ. 34 - 2 พ.ค. 34) | I12: 1/2566 | J12: 4 | K12: =ROUND(K9/6,1) -> 3.5 | L12: ห้ามลบ แถวนี้
A13: เวลาราชการ | E13: =E9+E11+E12 -> 32 | F13: =F9+F11+F12 -> 9 | G13: =G9+G11+G12 -> 0 | I13: 2/2565 | J13: 3.7 | L13: ห้ามลบ แถวนี้
A14: รวมเวลาราชการ | E14: =E13+(F13/12)+(G13/365) -> 32.75 | I14: 1/2565 | J14: 3.5 | L14: ห้ามลบ แถวนี้
L15: ห้ามลบ แถวนี้
A16: รอบการประเมิน | B16: ระดับตำแหน่ง | C16: เงินเดือนเดิม | D16: เงินเดือนขั้นสูง | E16: ฐาน | F16: % ที่เลื่อน (เฉลี่ย) | G16: เงินที่เลื่อน | H16: เงินที่เลื่อนจริง | I16: เงินเดือนใหม่ | J16: จำนวนเดือน | K16: เงินเดือนใหม่ x จำนวนเดือน | L16: ห้ามลบ แถวนี้
L17: ห้ามลบ แถวนี้
A18: 45566 | B18: ชำนาญการพิเศษ | C18: 49850 | D18: =INDEX(ฐานคำนวณ!$C$5:$C$19,MATCH(B18,ฐานคำนวณ!$B$5:$B$19,0)) -> 69040 | E18: =_xlfn.IFS(C18="","",C18>INDEX(ฐานคำนวณ!$F$5:$F$19,MATCH(B18,ฐานคำนวณ!$B$5:$B$19,0)),INDEX(ฐานคำนวณ!$D$5:$D$19,MATCH(B18,ฐานคำนวณ!$B$5:$B$19,0)),TRUE,INDEX(ฐานคำนวณ!$E$5:$E$19,MATCH(B18,ฐานคำนวณ!$B$5:$B$19,0))) -> 49330 | F18: 3.8 | G18: =ROUND(E18*F18%,2) -> 1874.54 | H18: =IF(C18+ROUNDUP(G18,-1)>=D18,D18-C18,ROUNDUP(G18,-1)) -> 1880 | I18: =C18+H18 -> 51730 | L18: ห้ามลบ แถวนี้
A19: 45748 | B19: ชำนาญการพิเศษ | C19: =I18 -> 51730 | D19: =INDEX(ฐานคำนวณ!$C$5:$C$19,MATCH(B19,ฐานคำนวณ!$B$5:$B$19,0)) -> 69040 | E19: =_xlfn.IFS(C19="","",C19>INDEX(ฐานคำนวณ!$F$5:$F$19,MATCH(B19,ฐานคำนวณ!$B$5:$B$19,0)),INDEX(ฐานคำนวณ!$D$5:$D$19,MATCH(B19,ฐานคำนวณ!$B$5:$B$19,0)),TRUE,INDEX(ฐานคำนวณ!$E$5:$E$19,MATCH(B19,ฐานคำนวณ!$B$5:$B$19,0))) -> 49330 | F19: 3.5 | G19: =ROUND(E19*F19%,2) -> 1726.55 | H19: =IF(C19+ROUNDUP(G19,-1)>=D19,D19-C19,ROUNDUP(G19,-1)) -> 1730 | I19: =C19+H19 -> 53460
A20: 45931 | B20: ชำนาญการพิเศษ | C20: =I19 -> 53460 | D20: =INDEX(ฐานคำนวณ!$C$5:$C$19,MATCH(B20,ฐานคำนวณ!$B$5:$B$19,0)) -> 69040 | E20: =_xlfn.IFS(C20="","",C20>INDEX(ฐานคำนวณ!$F$5:$F$19,MATCH(B20,ฐานคำนวณ!$B$5:$B$19,0)),INDEX(ฐานคำนวณ!$D$5:$D$19,MATCH(B20,ฐานคำนวณ!$B$5:$B$19,0)),TRUE,INDEX(ฐานคำนวณ!$E$5:$E$19,MATCH(B20,ฐานคำนวณ!$B$5:$B$19,0))) -> 49330 | F20: 3.5 | G20: =ROUND(E20*F20%,2) -> 1726.55 | H20: =IF(C20+ROUNDUP(G20,-1)>=D20,D20-C20,ROUNDUP(G20,-1)) -> 1730 | I20: =C20+H20 -> 55190
A21: 46113 | B21: อำนวยการต้น | C21: =I20 -> 55190 | D21: =INDEX(ฐานคำนวณ!$C$5:$C$19,MATCH(B21,ฐานคำนวณ!$B$5:$B$19,0)) -> 70360 | E21: =_xlfn.IFS(C21="","",C21>INDEX(ฐานคำนวณ!$F$5:$F$19,MATCH(B21,ฐานคำนวณ!$B$5:$B$19,0)),INDEX(ฐานคำนวณ!$D$5:$D$19,MATCH(B21,ฐานคำนวณ!$B$5:$B$19,0)),TRUE,INDEX(ฐานคำนวณ!$E$5:$E$19,MATCH(B21,ฐานคำนวณ!$B$5:$B$19,0))) -> 51290 | F21: 3.5 | G21: =ROUND(E21*F21%,2) -> 1795.15 | H21: =IF(C21+ROUNDUP(G21,-1)>=D21,D21-C21,ROUNDUP(G21,-1)) -> 1800 | I21: =C21+H21 -> 56990
A22: 46296 | B22: อำนวยการต้น | C22: =I21 -> 56990 | D22: =INDEX(ฐานคำนวณ!$C$5:$C$19,MATCH(B22,ฐานคำนวณ!$B$5:$B$19,0)) -> 70360 | E22: =_xlfn.IFS(C22="","",C22>INDEX(ฐานคำนวณ!$F$5:$F$19,MATCH(B22,ฐานคำนวณ!$B$5:$B$19,0)),INDEX(ฐานคำนวณ!$D$5:$D$19,MATCH(B22,ฐานคำนวณ!$B$5:$B$19,0)),TRUE,INDEX(ฐานคำนวณ!$E$5:$E$19,MATCH(B22,ฐานคำนวณ!$B$5:$B$19,0))) -> 51290 | F22: 3.5 | G22: =ROUND(E22*F22%,2) -> 1795.15 | H22: =IF(C22+ROUNDUP(G22,-1)>=D22,D22-C22,ROUNDUP(G22,-1)) -> 1800 | I22: =C22+H22 -> 58790
A23: 46478 | B23: อำนวยการต้น | C23: =I22 -> 58790 | D23: =INDEX(ฐานคำนวณ!$C$5:$C$19,MATCH(B23,ฐานคำนวณ!$B$5:$B$19,0)) -> 70360 | E23: =_xlfn.IFS(C23="","",C23>INDEX(ฐานคำนวณ!$F$5:$F$19,MATCH(B23,ฐานคำนวณ!$B$5:$B$19,0)),INDEX(ฐานคำนวณ!$D$5:$D$19,MATCH(B23,ฐานคำนวณ!$B$5:$B$19,0)),TRUE,INDEX(ฐานคำนวณ!$E$5:$E$19,MATCH(B23,ฐานคำนวณ!$B$5:$B$19,0))) -> 51290 | F23: 3.5 | G23: =ROUND(E23*F23%,2) -> 1795.15 | H23: =IF(C23+ROUNDUP(G23,-1)>=D23,D23-C23,ROUNDUP(G23,-1)) -> 1800 | I23: =C23+H23 -> 60590
A24: 46661 | B24: อำนวยการต้น | C24: =I23 -> 60590 | D24: =INDEX(ฐานคำนวณ!$C$5:$C$19,MATCH(B24,ฐานคำนวณ!$B$5:$B$19,0)) -> 70360 | E24: =_xlfn.IFS(C24="","",C24>INDEX(ฐานคำนวณ!$F$5:$F$19,MATCH(B24,ฐานคำนวณ!$B$5:$B$19,0)),INDEX(ฐานคำนวณ!$D$5:$D$19,MATCH(B24,ฐานคำนวณ!$B$5:$B$19,0)),TRUE,INDEX(ฐานคำนวณ!$E$5:$E$19,MATCH(B24,ฐานคำนวณ!$B$5:$B$19,0))) -> 51290 | F24: 3.5 | G24: =ROUND(E24*F24%,2) -> 1795.15 | H24: =IF(C24+ROUNDUP(G24,-1)>=D24,D24-C24,ROUNDUP(G24,-1)) -> 1800 | I24: =C24+H24 -> 62390
A25: 46844 | B25: อำนวยการต้น | C25: =I24 -> 62390 | D25: =INDEX(ฐานคำนวณ!$C$5:$C$19,MATCH(B25,ฐานคำนวณ!$B$5:$B$19,0)) -> 70360 | E25: =_xlfn.IFS(C25="","",C25>INDEX(ฐานคำนวณ!$F$5:$F$19,MATCH(B25,ฐานคำนวณ!$B$5:$B$19,0)),INDEX(ฐานคำนวณ!$D$5:$D$19,MATCH(B25,ฐานคำนวณ!$B$5:$B$19,0)),TRUE,INDEX(ฐานคำนวณ!$E$5:$E$19,MATCH(B25,ฐานคำนวณ!$B$5:$B$19,0))) -> 51290 | F25: 3.5 | G25: =ROUND(E25*F25%,2) -> 1795.15 | H25: =IF(C25+ROUNDUP(G25,-1)>=D25,D25-C25,ROUNDUP(G25,-1)) -> 1800 | I25: =C25+H25 -> 64190
A26: 47027 | B26: อำนวยการต้น | C26: =I25 -> 64190 | D26: =INDEX(ฐานคำนวณ!$C$5:$C$19,MATCH(B26,ฐานคำนวณ!$B$5:$B$19,0)) -> 70360 | E26: =_xlfn.IFS(C26="","",C26>INDEX(ฐานคำนวณ!$F$5:$F$19,MATCH(B26,ฐานคำนวณ!$B$5:$B$19,0)),INDEX(ฐานคำนวณ!$D$5:$D$19,MATCH(B26,ฐานคำนวณ!$B$5:$B$19,0)),TRUE,INDEX(ฐานคำนวณ!$E$5:$E$19,MATCH(B26,ฐานคำนวณ!$B$5:$B$19,0))) -> 51290 | F26: 3.5 | G26: =ROUND(E26*F26%,2) -> 1795.15 | H26: =IF(C26+ROUNDUP(G26,-1)>=D26,D26-C26,ROUNDUP(G26,-1)) -> 1800 | I26: =C26+H26 -> 65990
A27: 47209 | B27: อำนวยการต้น | C27: =I26 -> 65990 | D27: =INDEX(ฐานคำนวณ!$C$5:$C$19,MATCH(B27,ฐานคำนวณ!$B$5:$B$19,0)) -> 70360 | E27: =_xlfn.IFS(C27="","",C27>INDEX(ฐานคำนวณ!$F$5:$F$19,MATCH(B27,ฐานคำนวณ!$B$5:$B$19,0)),INDEX(ฐานคำนวณ!$D$5:$D$19,MATCH(B27,ฐานคำนวณ!$B$5:$B$19,0)),TRUE,INDEX(ฐานคำนวณ!$E$5:$E$19,MATCH(B27,ฐานคำนวณ!$B$5:$B$19,0))) -> 51290 | F27: 3.5 | G27: =ROUND(E27*F27%,2) -> 1795.15 | H27: =IF(C27+ROUNDUP(G27,-1)>=D27,D27-C27,ROUNDUP(G27,-1)) -> 1800 | I27: =C27+H27 -> 67790
A28: 47392 | B28: อำนวยการต้น | C28: =I27 -> 67790 | D28: =INDEX(ฐานคำนวณ!$C$5:$C$19,MATCH(B28,ฐานคำนวณ!$B$5:$B$19,0)) -> 70360 | E28: =_xlfn.IFS(C28="","",C28>INDEX(ฐานคำนวณ!$F$5:$F$19,MATCH(B28,ฐานคำนวณ!$B$5:$B$19,0)),INDEX(ฐานคำนวณ!$D$5:$D$19,MATCH(B28,ฐานคำนวณ!$B$5:$B$19,0)),TRUE,INDEX(ฐานคำนวณ!$E$5:$E$19,MATCH(B28,ฐานคำนวณ!$B$5:$B$19,0))) -> 51290 | F28: 3.5 | G28: =ROUND(E28*F28%,2) -> 1795.15 | H28: =IF(C28+ROUNDUP(G28,-1)>=D28,D28-C28,ROUNDUP(G28,-1)) -> 1800 | I28: =C28+H28 -> 69590
A29: 47574 | B29: อำนวยการต้น | C29: =I28 -> 69590 | D29: =INDEX(ฐานคำนวณ!$C$5:$C$19,MATCH(B29,ฐานคำนวณ!$B$5:$B$19,0)) -> 70360 | E29: =_xlfn.IFS(C29="","",C29>INDEX(ฐานคำนวณ!$F$5:$F$19,MATCH(B29,ฐานคำนวณ!$B$5:$B$19,0)),INDEX(ฐานคำนวณ!$D$5:$D$19,MATCH(B29,ฐานคำนวณ!$B$5:$B$19,0)),TRUE,INDEX(ฐานคำนวณ!$E$5:$E$19,MATCH(B29,ฐานคำนวณ!$B$5:$B$19,0))) -> 51290 | F29: 3.5 | G29: =ROUND(E29*F29%,2) -> 1795.15 | H29: =IF(C29+ROUNDUP(G29,-1)>=D29,D29-C29,ROUNDUP(G29,-1)) -> 770 | I29: =C29+H29 -> 70360
A30: 47757 | B30: อำนวยการต้น | C30: =I29 -> 70360 | D30: =INDEX(ฐานคำนวณ!$C$5:$C$19,MATCH(B30,ฐานคำนวณ!$B$5:$B$19,0)) -> 70360 | E30: =_xlfn.IFS(C30="","",C30>INDEX(ฐานคำนวณ!$F$5:$F$19,MATCH(B30,ฐานคำนวณ!$B$5:$B$19,0)),INDEX(ฐานคำนวณ!$D$5:$D$19,MATCH(B30,ฐานคำนวณ!$B$5:$B$19,0)),TRUE,INDEX(ฐานคำนวณ!$E$5:$E$19,MATCH(B30,ฐานคำนวณ!$B$5:$B$19,0))) -> 51290 | F30: 3.5 | G30: =ROUND(E30*F30%,2) -> 1795.15 | H30: =IF(C30+ROUNDUP(G30,-1)>=D30,D30-C30,ROUNDUP(G30,-1)) -> 0 | I30: =C30+H30 -> 70360
A31: 47939 | B31: อำนวยการต้น | C31: =I30 -> 70360 | D31: =INDEX(ฐานคำนวณ!$C$5:$C$19,MATCH(B31,ฐานคำนวณ!$B$5:$B$19,0)) -> 70360 | E31: =_xlfn.IFS(C31="","",C31>INDEX(ฐานคำนวณ!$F$5:$F$19,MATCH(B31,ฐานคำนวณ!$B$5:$B$19,0)),INDEX(ฐานคำนวณ!$D$5:$D$19,MATCH(B31,ฐานคำนวณ!$B$5:$B$19,0)),TRUE,INDEX(ฐานคำนวณ!$E$5:$E$19,MATCH(B31,ฐานคำนวณ!$B$5:$B$19,0))) -> 51290 | F31: 3.5 | G31: =ROUND(E31*F31%,2) -> 1795.15 | H31: =IF(C31+ROUNDUP(G31,-1)>=D31,D31-C31,ROUNDUP(G31,-1)) -> 0 | I31: =C31+H31 -> 70360
A32: 48122 | B32: อำนวยการต้น | C32: =I31 -> 70360 | D32: =INDEX(ฐานคำนวณ!$C$5:$C$19,MATCH(B32,ฐานคำนวณ!$B$5:$B$19,0)) -> 70360 | E32: =_xlfn.IFS(C32="","",C32>INDEX(ฐานคำนวณ!$F$5:$F$19,MATCH(B32,ฐานคำนวณ!$B$5:$B$19,0)),INDEX(ฐานคำนวณ!$D$5:$D$19,MATCH(B32,ฐานคำนวณ!$B$5:$B$19,0)),TRUE,INDEX(ฐานคำนวณ!$E$5:$E$19,MATCH(B32,ฐานคำนวณ!$B$5:$B$19,0))) -> 51290 | F32: 3.5 | G32: =ROUND(E32*F32%,2) -> 1795.15 | H32: =IF(C32+ROUNDUP(G32,-1)>=D32,D32-C32,ROUNDUP(G32,-1)) -> 0 | I32: =C32+H32 -> 70360 | J32: 6 | K32: =I32*J32 -> 422160
A33: 48305 | B33: อำนวยการสูง | C33: =I32 -> 70360 | D33: =INDEX(ฐานคำนวณ!$C$5:$C$19,MATCH(B33,ฐานคำนวณ!$B$5:$B$19,0)) -> 74320 | E33: =_xlfn.IFS(C33="","",C33>INDEX(ฐานคำนวณ!$F$5:$F$19,MATCH(B33,ฐานคำนวณ!$B$5:$B$19,0)),INDEX(ฐานคำนวณ!$D$5:$D$19,MATCH(B33,ฐานคำนวณ!$B$5:$B$19,0)),TRUE,INDEX(ฐานคำนวณ!$E$5:$E$19,MATCH(B33,ฐานคำนวณ!$B$5:$B$19,0))) -> 60990 | F33: 3.5 | G33: =ROUND(E33*F33%,2) -> 2134.65 | H33: =IF(C33+ROUNDUP(G33,-1)>=D33,D33-C33,ROUNDUP(G33,-1)) -> 2140 | I33: =C33+H33 -> 72500 | J33: 6 | K33: =I33*J33 -> 435000 | L33: 6
A34: 48488 | B34: อำนวยการสูง | C34: =I33 -> 72500 | D34: =INDEX(ฐานคำนวณ!$C$5:$C$19,MATCH(B34,ฐานคำนวณ!$B$5:$B$19,0)) -> 74320 | E34: =_xlfn.IFS(C34="","",C34>INDEX(ฐานคำนวณ!$F$5:$F$19,MATCH(B34,ฐานคำนวณ!$B$5:$B$19,0)),INDEX(ฐานคำนวณ!$D$5:$D$19,MATCH(B34,ฐานคำนวณ!$B$5:$B$19,0)),TRUE,INDEX(ฐานคำนวณ!$E$5:$E$19,MATCH(B34,ฐานคำนวณ!$B$5:$B$19,0))) -> 60990 | F34: 3.5 | G34: =ROUND(E34*F34%,2) -> 2134.65 | H34: =IF(C34+ROUNDUP(G34,-1)>=D34,D34-C34,ROUNDUP(G34,-1)) -> 1820 | I34: =C34+H34 -> 74320 | J34: 6 | K34: =I34*J34 -> 445920 | L34: 6
A35: 48670 | B35: อำนวยการสูง | C35: =I34 -> 74320 | D35: =INDEX(ฐานคำนวณ!$C$5:$C$19,MATCH(B35,ฐานคำนวณ!$B$5:$B$19,0)) -> 74320 | E35: =_xlfn.IFS(C35="","",C35>INDEX(ฐานคำนวณ!$F$5:$F$19,MATCH(B35,ฐานคำนวณ!$B$5:$B$19,0)),INDEX(ฐานคำนวณ!$D$5:$D$19,MATCH(B35,ฐานคำนวณ!$B$5:$B$19,0)),TRUE,INDEX(ฐานคำนวณ!$E$5:$E$19,MATCH(B35,ฐานคำนวณ!$B$5:$B$19,0))) -> 60990 | F35: 3.5 | G35: =ROUND(E35*F35%,2) -> 2134.65 | H35: =IF(C35+ROUNDUP(G35,-1)>=D35,D35-C35,ROUNDUP(G35,-1)) -> 0 | I35: =C35+H35 -> 74320 | J35: 6 | K35: =I35*J35 -> 445920 | L35: 6
A36: 48853 | B36: อำนวยการสูง | C36: =I35 -> 74320 | D36: =INDEX(ฐานคำนวณ!$C$5:$C$19,MATCH(B36,ฐานคำนวณ!$B$5:$B$19,0)) -> 74320 | E36: =_xlfn.IFS(C36="","",C36>INDEX(ฐานคำนวณ!$F$5:$F$19,MATCH(B36,ฐานคำนวณ!$B$5:$B$19,0)),INDEX(ฐานคำนวณ!$D$5:$D$19,MATCH(B36,ฐานคำนวณ!$B$5:$B$19,0)),TRUE,INDEX(ฐานคำนวณ!$E$5:$E$19,MATCH(B36,ฐานคำนวณ!$B$5:$B$19,0))) -> 60990 | F36: 3.5 | G36: =ROUND(E36*F36%,2) -> 2134.65 | H36: =IF(C36+ROUNDUP(G36,-1)>=D36,D36-C36,ROUNDUP(G36,-1)) -> 0 | I36: =C36+H36 -> 74320 | J36: 6 | K36: =I36*J36 -> 445920 | L36: 6
A37: 49035 | B37: อำนวยการสูง | C37: =I36 -> 74320 | D37: =INDEX(ฐานคำนวณ!$C$5:$C$19,MATCH(B37,ฐานคำนวณ!$B$5:$B$19,0)) -> 74320 | E37: =_xlfn.IFS(C37="","",C37>INDEX(ฐานคำนวณ!$F$5:$F$19,MATCH(B37,ฐานคำนวณ!$B$5:$B$19,0)),INDEX(ฐานคำนวณ!$D$5:$D$19,MATCH(B37,ฐานคำนวณ!$B$5:$B$19,0)),TRUE,INDEX(ฐานคำนวณ!$E$5:$E$19,MATCH(B37,ฐานคำนวณ!$B$5:$B$19,0))) -> 60990 | F37: 3.5 | G37: =ROUND(E37*F37%,2) -> 2134.65 | H37: =IF(C37+ROUNDUP(G37,-1)>=D37,D37-C37,ROUNDUP(G37,-1)) -> 0 | I37: =C37+H37 -> 74320 | J37: 6 | K37: =I37*J37 -> 445920 | L37: 6
A38: 49218 | B38: อำนวยการสูง | C38: =I37 -> 74320 | D38: =INDEX(ฐานคำนวณ!$C$5:$C$19,MATCH(B38,ฐานคำนวณ!$B$5:$B$19,0)) -> 74320 | E38: =_xlfn.IFS(C38="","",C38>INDEX(ฐานคำนวณ!$F$5:$F$19,MATCH(B38,ฐานคำนวณ!$B$5:$B$19,0)),INDEX(ฐานคำนวณ!$D$5:$D$19,MATCH(B38,ฐานคำนวณ!$B$5:$B$19,0)),TRUE,INDEX(ฐานคำนวณ!$E$5:$E$19,MATCH(B38,ฐานคำนวณ!$B$5:$B$19,0))) -> 60990 | F38: 3.5 | G38: =ROUND(E38*F38%,2) -> 2134.65 | H38: =IF(C38+ROUNDUP(G38,-1)>=D38,D38-C38,ROUNDUP(G38,-1)) -> 0 | I38: =C38+H38 -> 74320 | J38: 6 | K38: =I38*J38 -> 445920 | L38: 6
A39: 49400 | B39: อำนวยการสูง | C39: =I38 -> 74320 | D39: =INDEX(ฐานคำนวณ!$C$5:$C$19,MATCH(B39,ฐานคำนวณ!$B$5:$B$19,0)) -> 74320 | E39: =_xlfn.IFS(C39="","",C39>INDEX(ฐานคำนวณ!$F$5:$F$19,MATCH(B39,ฐานคำนวณ!$B$5:$B$19,0)),INDEX(ฐานคำนวณ!$D$5:$D$19,MATCH(B39,ฐานคำนวณ!$B$5:$B$19,0)),TRUE,INDEX(ฐานคำนวณ!$E$5:$E$19,MATCH(B39,ฐานคำนวณ!$B$5:$B$19,0))) -> 60990 | F39: 3.5 | G39: =ROUND(E39*F39%,2) -> 2134.65 | H39: =IF(C39+ROUNDUP(G39,-1)>=D39,D39-C39,ROUNDUP(G39,-1)) -> 0 | I39: =C39+H39 -> 74320 | J39: 6 | K39: =I39*J39 -> 445920 | L39: 6
A40: 49583 | B40: อำนวยการสูง | C40: =I39 -> 74320 | D40: =INDEX(ฐานคำนวณ!$C$5:$C$19,MATCH(B40,ฐานคำนวณ!$B$5:$B$19,0)) -> 74320 | E40: =_xlfn.IFS(C40="","",C40>INDEX(ฐานคำนวณ!$F$5:$F$19,MATCH(B40,ฐานคำนวณ!$B$5:$B$19,0)),INDEX(ฐานคำนวณ!$D$5:$D$19,MATCH(B40,ฐานคำนวณ!$B$5:$B$19,0)),TRUE,INDEX(ฐานคำนวณ!$E$5:$E$19,MATCH(B40,ฐานคำนวณ!$B$5:$B$19,0))) -> 60990 | F40: 3.5 | G40: =ROUND(E40*F40%,2) -> 2134.65 | H40: =IF(C40+ROUNDUP(G40,-1)>=D40,D40-C40,ROUNDUP(G40,-1)) -> 0 | I40: =C40+H40 -> 74320 | J40: 6 | K40: =I40*J40 -> 445920 | L40: 6
...
